<?xml version="1.0" ?>
<robot name="my_robotic_arm">

  <!-- Define the joint types -->
  <joint name="base_to_link1" type="fixed">
    <origin xyz="0 0 0" rpy="0 0 0" />
    <parent link="base_link" />
    <child link="link1" />
  </joint>

  <joint name="link1_to_link2" type="revolute">
    <origin xyz="0 0 0.2" rpy="0 0 0" />
    <parent link="link1" />
    <child link="link2" />
    <axis xyz="0 1 0" />
    <limit lower="-3.1416" upper="3.1416" effort="100" velocity="3.14" />
  </joint>

  <joint name="link2_to_link3" type="revolute">
    <origin xyz="0 0.4 0" rpy="0 0 0" />
    <parent link="link2" />
    <child link="link3" />
    <axis xyz="0 1 0" />
    <limit lower="-3.1416" upper="3.1416" effort="100" velocity="3.14" />
  </joint>

  <joint name="link3_to_link4" type="revolute">
    <origin xyz="0 0.4 0" rpy="0 0 0" />
    <parent link="link3" />
    <child link="link4" />
    <axis xyz="0 1 0" />
    <limit lower="-3.1416" upper="3.1416" effort="100" velocity="3.14" />
  </joint>

  <joint name="link4_to_link5" type="revolute">
    <origin xyz="0 0.4 0" rpy="0 0 0" />
    <parent link="link4" />
    <child link="link5" />
    <axis xyz="0 1 0" />
    <limit lower="-3.1416" upper="3.1416" effort="100" velocity="3.14" />
  </joint>

  <joint name="link5_to_link6" type="revolute">
    <origin xyz="0 0.4 0" rpy="0 0 0" />
    <parent link="link5" />
    <child link="link6" />
    <axis xyz="0 1 0" />
    <limit lower="-3.1416" upper="3.1416" effort="100" velocity="3.14" />
  </joint>

  <!-- Define the links -->
  <link name="base_link" />

  <link name="link1">
    <visual>
      <geometry>
        <cylinder length="0.2" radius="0.05" />
      </geometry>
    </visual>
    <collision>
      <geometry>
        <cylinder length="0.2" radius="0.05" />
      </geometry>
    </collision>
  </link>

  <link name="link2">
    <visual>
      <geometry>
        <cylinder length="0.4" radius="0.03" />
      </geometry>
    </visual>
    <collision>
      <geometry>
        <cylinder length="0.4" radius="0.03" />
      </geometry>
    </collision>
  </link>

  <link name="link3">
    <visual>
      <geometry>
        <cylinder length="0.4" radius="0.025" />
      </geometry>
    </visual>
    <collision>
      <geometry>
        <cylinder length="0.4" radius="0.025" />
      </geometry>
    </collision>
  </link>

  <link name="link4">
    <visual>
      <geometry>
        <cylinder length="0.4" radius="0.02" />
      </geometry>
    </visual>
    <collision>
      <geometry>
        <cylinder length="0.4" radius="0.02" />
      </geometry>
    </collision>
  </link>

  <link name="link5">
    <visual>
      <geometry>
        <cylinder length="0.4" radius="0.015" />
      </geometry>
    </visual>
    <collision>
      <geometry>
        <cylinder length="0.4" radius="0.015" />
      </geometry>
    </collision>
  </link>

  <link name="link6">
    <visual>
      <geometry>
        <cylinder length="0.4" radius="0.01" />
      </geometry>
    </visual>
    <collision>
      <geometry>
        <cylinder length="0.4" radius="0.01" />
      </geometry>
    </collision>
  </link>

</robot>
